Workbook

Sheet Hypothèses
B1: IPAA — HYPOTHÈSES DU MODÈLE | Cabin Skolar 2025
B2: Valeurs en bleu = modifiables · Les feuilles de calcul utilisent les valeurs directement
B4: MACRO-ÉCONOMIQUE
B5: PIB 2025 (Md€) | C5: 2900 | D5: INSEE 2025
B6: Croissance productivité/an | C6: 0.007 | D6: COR 2025 scénario B
B7: Inflation cible | C7: 0.02 | D7: BCE objectif 2%
B8: Taux chômage structurel | C8: 0.07 | D8: COR 2025 — 7%
B9: Part masse salariale / PIB | C9: 0.542 | D9: INSEE 2024
B10: SYSTÈME RETRAITE — ÉTAT INITIAL
B11: Dépenses retraite 2025 (Md€) | C11: 345 | D11: DREES 2024
B12: Recettes cotisations 2025 (Md€) | C12: 330.5 | D12: DREES 2024
B13: Taux cotisation socle τ₀ | C13: 0.28 | D13: Taux effectif moyen
B14: Taux exonérations non compensées | C14: 0.065 | D14: DREES estimé 6,5%
B15: DÉMOGRAPHIE
B16: Ratio actifs/retraités 2025 | C16: 1.7 | D16: COR 2025 / INSEE
B17: Ratio 2040 — scénario central | C17: 1.5 | D17: COR 2025 scénario B
B18: Ratio 2050 — scénario central | C18: 1.42 | D18: COR 2025 scénario B
B19: Ratio 2040 — scénario bas (R1) | C19: 1.38 | D19: COR 2025 scénario C
B20: Ratio 2050 — scénario bas (R1) | C20: 1.25 | D20: COR 2025 scénario C
B21: FRR
B22: Actifs FRR 2025 (Md€) | C22: 26.2 | D22: FRR Rapport 2023
B23: Part socle souverain | C23: 0.3 | D23: 30% intouchable — convention modèle
B24: Rendement central (r_frr) | C24: 0.05 | D24: V2 révisé — 5% contraintes prudentielles FR
B25: Rendement optimiste (si réforme gouv.) | C25: 0.075 | D25: Conditionnel — type RPC Canada 9,1%
B26: Rendement bas — stress R3 | C26: 0.02 | D26: Stress test type 2008-2018
B27: CFРР (% actifs FRR) | C27: 0.1 | D27: Capacité lissage annuelle — CETP
B28: Taux réinvestissement rendements | C28: 0.7 | D28: 70% réinvestis — 30% réserve lissage
B29: PARAMÈTRES AC-IPAA
B30: Plafond ∆τ annuel (pts cotisation) | C30: 0.001 | D30: 0,1 pt/an max — proposition CETP
B31: ∆τ accumulé maximum absolu | C31: 0.02 | D31: 2 pts sur toute la durée
B32: Marge sécurité S_cible (% PIB) | C32: 0.001 | D32: 0,1% PIB — cible léger excédent
B33: Absorption péréquation N0 (% EReq) | C33: 0.2 | D33: Estimation — 20% absorbé par N0
B34: Taux actualisation EReq | C34: 0.02 | D34: Convention modèle
B35: NOUVELLES ASSIETTES
B36: Cotisation plateformes numériques (Md€/an) | C36: 1.1 | D36: 1-1,5% CA plateformes en FR
B37: Cotisation capital phase active (Md€/an) | C37: 0.6 | D37: 0,5-1% revenus PEA/AV
B38: Contribution différée exonérations (Md€/an) | C38: 1.8 | D38: 15-20% économie réalisée → FRR
B39: DÉCILE — Revenu médian net/mois (€) — βi
B40: D1 | C40: 800 | D40: 0
B41: D2 | C41: 1100 | D41: 0
...

Sheet Modèle_30ans
B1: IPAA — MODÈLE DYNAMIQUE 30 ANS | Cabin Skolar 2025 | Sources: COR 2025, INSEE, DREES, FRR
B2: Indicateur | C2: Unité | D2: 2025 | E2: 2026 | F2: 2027 | G2: 2028 | H2: 2029 | I2: 2030 | J2: 2031 | K2: 2032 | L2: 2033 | M2: 2034 | N2: 2035 | O2: 2036 | P2: 2037 | Q2: 2038 | R2: 2039 | S2: 2040 | T2: 2041 | U2: 2042 | V2: 2043 | W2: 2044 | X2: 2045 | Y2: 2046 | Z2: 2047 | AA2: 2048 | AB2: 2049 | AC2: 2050 | AD2: 2051 | AE2: 2052 | AF2: 2053 | AG2: 2054 | AH2: 2055
B3: A. CROISSANCE ÉCONOMIQUE
B4: PIB France | C4: Md€ | D4: =Hypothèses!$C$5 -> 2900 | E4: =D4*(1+Hypothèses!$C$6+Hypothèses!$C$8*(1-Hypothèses!$C$8)/10) -> 2939.179 | F4: =E4*(1+Hypothèses!$C$6+Hypothèses!$C$8*(1-Hypothèses!$C$8)/10) -> 2978.8873 | G4: =F4*(1+Hypothèses!$C$6+Hypothèses!$C$8*(1-Hypothèses!$C$8)/10) -> 3019.1321 | H4: =G4*(1+Hypothèses!$C$6+Hypothèses!$C$8*(1-Hypothèses!$C$8)/10) -> 3059.9206 | I4: =H4*(1+Hypothèses!$C$6+Hypothèses!$C$8*(1-Hypothèses!$C$8)/10) -> 3101.2601 | J4: =I4*(1+Hypothèses!$C$6+Hypothèses!$C$8*(1-Hypothèses!$C$8)/10) -> 3143.1581 | K4: =J4*(1+Hypothèses!$C$6+Hypothèses!$C$8*(1-Hypothèses!$C$8)/10) -> 3185.6222 | L4: =K4*(1+Hypothèses!$C$6+Hypothèses!$C$8*(1-Hypothèses!$C$8)/10) -> 3228.6599 | ... AH4: =AG4*(1+Hypothèses!$C$6+Hypothèses!$C$8*(1-Hypothèses!$C$8)/10) -> 4337.4965
B5: Masse salariale M(t) | C5: Md€ | D5: =D4*Hypothèses!$C$9 -> 1571.8 | E5: =E4*Hypothèses!$C$9 -> 1593.035 | F5: =F4*Hypothèses!$C$9 -> 1614.5569 | G5: =G4*Hypothèses!$C$9 -> 1636.3696 | H5: =H4*Hypothèses!$C$9 -> 1658.4769 | I5: =I4*Hypothèses!$C$9 -> 1680.883 | J5: =J4*Hypothèses!$C$9 -> 1703.5917 | K5: =K4*Hypothèses!$C$9 -> 1726.6072 | ... AH5: =AH4*Hypothèses!$C$9 -> 2350.9231
B6: B. DÉMOGRAPHIE — RATIO ACTIFS/RETRAITÉS
B7: Ratio actifs/retraités — central | C7: ratio | D7: =Hypothèses!$C$16 -> 1.7 | E7: =Hypothèses!$C$16+(2026-2025)/(2040-2025)*(Hypothèses!$C$17-Hypothèses!$C$16) -> 1.6866667 | F7: =Hypothèses!$C$16+(2027-2025)/(2040-2025)*(Hypothèses!$C$17-Hypothèses!$C$16) -> 1.6733333 | G7: =Hypothèses!$C$16+(2028-2025)/(2040-2025)*(Hypothèses!$C$17-Hypothèses!$C$16) -> 1.66 | H7: =Hypothèses!$C$16+(2029-2025)/(2040-2025)*(Hypothèses!$C$17-Hypothèses!$C$16) -> 1.6466667 | I7: =Hypothèses!$C$16+(2030-2025)/(2040-2025)*(Hypothèses!$C$17-Hypothèses!$C$16) -> 1.6333333 | J7: =Hypothèses!$C$16+(2031-2025)/(2040-2025)*(Hypothèses!$C$17-Hypothèses!$C$16) -> 1.62 | K7: =Hypothèses!$C$16+(2032-2025)/(2040-2025)*(Hypothèses!$C$17-Hypothèses!$C$16) -> 1.6066667 | L7: =Hypothèses!$C$16+(2033-2025)/(2040-2025)*(Hypothèses!$C$17-Hypothèses!$C$16) -> 1.5933333 | M7: =Hypothèses!$C$16+(2034-2025)/(2040-2025)*(Hypothèses!$C$17-Hypothèses!$C$16) -> 1.58 | N7: =Hypothèses!$C$16+(2035-2025)/(2040-2025)*(Hypothèses!$C$17-Hypothèses!$C$16) -> 1.5666667 | O7: =Hypothèses!$C$16+(2036-2025)/(2040-2025)*(Hypothèses!$C$17-Hypothèses!$C$16) -> 1.5533333 | P7: =Hypothèses!$C$16+(2037-2025)/(2040-2025)*(Hypothèses!$C$17-Hypothèses!$C$16) -> 1.54 | Q7: =Hypothèses!$C$16+(2038-2025)/(2040-2025)*(Hypothèses!$C$17-Hypothèses!$C$16) -> 1.5266667 | R7: =Hypothèses!$C$16+(2039-2025)/(2040-2025)*(Hypothèses!$C$17-Hypothèses!$C$16) -> 1.5133333 | S7: =Hypothèses!$C$16+(2040-2025)/(2040-2025)*(Hypothèses!$C$17-Hypothèses!$C$16) -> 1.5 | T7: =Hypothèses!$C$17+(2041-2040)/(2050-2040)*(Hypothèses!$C$18-Hypothèses!$C$17) -> 1.492 | U7: =Hypothèses!$C$17+(2042-2040)/(2050-2040)*(Hypothèses!$C$18-Hypothèses!$C$17) -> 1.484 | V7: =Hypothèses!$C$17+(2043-2040)/(2050-2040)*(Hypothèses!$C$18-Hypothèses!$C$17) -> 1.476 | W7: =Hypothèses!$C$17+(2044-2040)/(2050-2040)*(Hypothèses!$C$18-Hypothèses!$C$17) -> 1.468 | X7: =Hypothèses!$C$17+(2045-2040)/(2050-2040)*(Hypothèses!$C$18-Hypothèses!$C$17) -> 1.46 | Y7: =Hypothèses!$C$17+(2046-2040)/(2050-2040)*(Hypothèses!$C$18-Hypothèses!$C$17) -> 1.452 | Z7: =Hypothèses!$C$17+(2047-2040)/(2050-2040)*(Hypothèses!$C$18-Hypothèses!$C$17) -> 1.444 | AA7: =Hypothèses!$C$17+(2048-2040)/(2050-2040)*(Hypothèses!$C$18-Hypothèses!$C$17) -> 1.436 | AB7: =Hypothèses!$C$17+(2049-2040)/(2050-2040)*(Hypothèses!$C$18-Hypothèses!$C$17) -> 1.428 | AC7: =Hypothèses!$C$17+(2050-2040)/(2050-2040)*(Hypothèses!$C$18-Hypothèses!$C$17) -> 1.42 | AD7: =Hypothèses!$C$18+(2051-2050)*(-0.002) -> 1.418 | AE7: =Hypothèses!$C$18+(2052-2050)*(-0.002) -> 1.416 | AF7: =Hypothèses!$C$18+(2053-2050)*(-0.002) -> 1.414 | AG7: =Hypothèses!$C$18+(2054-2050)*(-0.002) -> 1.412 | AH7: =Hypothèses!$C$18+(2055-2050)*(-0.002) -> 1.41
B8: Ratio actifs/retraités — bas (R1) | C8: ratio | D8: =Hypothèses!$C$16 -> 1.7 | E8: =Hypothèses!$C$16+(2026-2025)/(2040-2025)*(Hypothèses!$C$19-Hypothèses!$C$16) -> 1.6786667 | F8: =Hypothèses!$C$16+(2027-2025)/(2040-2025)*(Hypothèses!$C$19-Hypothèses!$C$16) -> 1.6573333 | G8: =Hypothèses!$C$16+(2028-2025)/(2040-2025)*(Hypothèses!$C$19-Hypothèses!$C$16) -> 1.636 | H8: =Hypothèses!$C$16+(2029-2025)/(2040-2025)*(Hypothèses!$C$19-Hypothèses!$C$16) -> 1.6146667 | I8: =Hypothèses!$C$16+(2030-2025)/(2040-2025)*(Hypothèses!$C$19-Hypothèses!$C$16) -> 1.5933333 | J8: =Hypothèses!$C$16+(2031-2025)/(2040-2025)*(Hypothèses!$C$19-Hypothèses!$C$16) -> 1.572 | K8: =Hypothèses!$C$16+(2032-2025)/(2040-2025)*(Hypothèses!$C$19-Hypothèses!$C$16) -> 1.5506667 | L8: =Hypothèses!$C$16+(2033-2025)/(2040-2025)*(Hypothèses!$C$19-Hypothèses!$C$16) -> 1.5293333 | M8: =Hypothèses!$C$16+(2034-2025)/(2040-2025)*(Hypothèses!$C$19-Hypothèses!$C$16) -> 1.508 | N8: =Hypothèses!$C$16+(2035-2025)/(2040-2025)*(Hypothèses!$C$19-Hypothèses!$C$16) -> 1.4866667 | O8: =Hypothèses!$C$16+(2036-2025)/(2040-2025)*(Hypothèses!$C$19-Hypothèses!$C$16) -> 1.4653333 | P8: =Hypothèses!$C$16+(2037-2025)/(2040-2025)*(Hypothèses!$C$19-Hypothèses!$C$16) -> 1.444 | Q8: =Hypothèses!$C$16+(2038-2025)/(2040-2025)*(Hypothèses!$C$19-Hypothèses!$C$16) -> 1.4226667 | R8: =Hypothèses!$C$16+(2039-2025)/(2040-2025)*(Hypothèses!$C$19-Hypothèses!$C$16) -> 1.4013333 | S8: =Hypothèses!$C$16+(2040-2025)/(2040-2025)*(Hypothèses!$C$19-Hypothèses!$C$16) -> 1.38 | T8: =Hypothèses!$C$19+(2041-2040)/(2050-2040)*(Hypothèses!$C$20-Hypothèses!$C$19) -> 1.367 | U8: =Hypothèses!$C$19+(2042-2040)/(2050-2040)*(Hypothèses!$C$20-Hypothèses!$C$19) -> 1.354 | V8: =Hypothèses!$C$19+(2043-2040)/(2050-2040)*(Hypothèses!$C$20-Hypothèses!$C$19) -> 1.341 | W8: =Hypothèses!$C$19+(2044-2040)/(2050-2040)*(Hypothèses!$C$20-Hypothèses!$C$19) -> 1.328 | X8: =Hypothèses!$C$19+(2045-2040)/(2050-2040)*(Hypothèses!$C$20-Hypothèses!$C$19) -> 1.315 | Y8: =Hypothèses!$C$19+(2046-2040)/(2050-2040)*(Hypothèses!$C$20-Hypothèses!$C$19) -> 1.302 | Z8: =Hypothèses!$C$19+(2047-2040)/(2050-2040)*(Hypothèses!$C$20-Hypothèses!$C$19) -> 1.289 | AA8: =Hypothèses!$C$19+(2048-2040)/(2050-2040)*(Hypothèses!$C$20-Hypothèses!$C$19) -> 1.276 | AB8: =Hypothèses!$C$19+(2049-2040)/(2050-2040)*(Hypothèses!$C$20-Hypothèses!$C$19) -> 1.263 | AC8: =Hypothèses!$C$19+(2050-2040)/(2050-2040)*(Hypothèses!$C$20-Hypothèses!$C$19) -> 1.25 | AD8: =Hypothèses!$C$20+(2051-2050)*(-0.003) -> 1.247 | AE8: =Hypothèses!$C$20+(2052-2050)*(-0.003) -> 1.244 | AF8: =Hypothèses!$C$20+(2053-2050)*(-0.003) -> 1.241 | AG8: =Hypothèses!$C$20+(2054-2050)*(-0.003) -> 1.238 | AH8: =Hypothèses!$C$20+(2055-2050)*(-0.003) -> 1.235
B9: C. SYSTÈME DE RETRAITE — SANS IPAA
B10: Dépenses retraite D(t) | C10: Md€ | D10: =Hypothèses!$C$11 -> 345 | E10: =D10*(1+Hypothèses!$C$7*0.95)*IF(AND(D7>0,E7>0),(E7/D7+1)/2,1) -> 350.17635 | F10: =E10*(1+Hypothèses!$C$7*0.95)*IF(AND(E7>0,F7>0),(F7/E7+1)/2,1) -> 355.41931 | G10: =F10*(1+Hypothèses!$C$7*0.95)*IF(AND(F7>0,G7>0),(G7/F7+1)/2,1) -> 360.72936 | H10: =G10*(1+Hypothèses!$C$7*0.95)*IF(AND(G7>0,H7>0),(H7/G7+1)/2,1) -> 366.10698 | I10: =H10*(1+Hypothèses!$C$7*0.95)*IF(AND(H7>0,I7>0),(I7/H7+1)/2,1) -> 371.55264 | J10: =I10*(1+Hypothèses!$C$7*0.95)*IF(AND(I7>0,J7>0),(J7/I7+1)/2,1) -> 377.06678 | K10: =J10*(1+Hypothèses!$C$7*0.95)*IF(AND(J7>0,K7>0),(K7/J7+1)/2,1) -> 382.64985 | L10: =K10*(1+Hypothèses!$C$7*0.95)*IF(AND(K7>0,L7>0),(L7/K7+1)/2,1) -> 388.30227 | ... AH10: =AG10*(1+Hypothèses!$C$7*0.95)*IF(AND(AG7>0,AH7>0),(AH7/AG7+1)/2,1) -> 552.71765
B11: Recettes cotisations R(t) sans IPAA | C11: Md€ | D11: =Hypothèses!$C$12 -> 330.5 | E11: =E5*Hypothèses!$C$13*(1-Hypothèses!$C$14) -> 417.05657 | F11: =F5*Hypothèses!$C$13*(1-Hypothèses!$C$14) -> 422.691 | G11: =G5*Hypothèses!$C$13*(1-Hypothèses!$C$14) -> 428.40156 | H11: =H5*Hypothèses!$C$13*(1-Hypothèses!$C$14) -> 434.18926 | I11: =I5*Hypothèses!$C$13*(1-Hypothèses!$C$14) -> 440.05516 | J11: =J5*Hypothèses!$C$13*(1-Hypothèses!$C$14) -> 446.0003 | K11: =K5*Hypothèses!$C$13*(1-Hypothèses!$C$14) -> 452.02577 | L11: =L5*Hypothèses!$C$13*(1-Hypothèses!$C$14) -> 458.13264 | ... AH11: =AH5*Hypothèses!$C$13*(1-Hypothèses!$C$14) -> 615.47167
B12: Solde structurel Δ(t) = R − D | C12: Md€ | D12: =D11-D10 -> -14.5 | E12: =E11-E10 -> 66.880215 | F12: =F11-F10 -> 67.271692 | G12: =G11-G10 -> 67.672198 | H12: =H11-H10 -> 68.082283 | I12: =I11-I10 -> 68.502524 | J12: =J11-J10 -> 68.933525 | K12: =K11-K10 -> 69.375918 | ... AH12: =AH11-AH10 -> 62.754022
B13: Solde en % du PIB — SANS IPAA | C13: %PIB | D13: =IFERROR(D12/D4,0) -> -0.005 | E13: =IFERROR(E12/E4,0) -> 0.022754727 | F13: =IFERROR(F12/F4,0) -> 0.022582826 | G13: =IFERROR(G12/G4,0) -> 0.022414454 | H13: =IFERROR(H12/H4,0) -> 0.02224969 | I13: =IFERROR(I12/I4,0) -> 0.02208861 | J13: =IFERROR(J12/J4,0) -> 0.021931294 | K13: =IFERROR(K12/K4,0) -> 0.021777824 | ... AH13: =IFERROR(AH12/AH4,0) -> 0.014467798
B14: EReq(t) = déficit moyen actualisé N+5 + S_cible | C14: Md€ | D14: =(IFERROR(-D12/(1+Hypothèses!$C$34)^1,0)+IFERROR(-E12/(1+Hypothèses!$C$34)^2,0)+IFERROR(-F12/(1+Hypothèses!$C$34)^3,0)+IFERROR(-G12/(1+Hypothèses!$C$34)^4,0)+IFERROR(-H12/(1+Hypothèses!$C$34)^5,0))/5+IFERROR(Hypothèses!$C$32*D4,0) -> -44.628396 | E14: =(IFERROR(-E12/(1+Hypothèses!$C$34)^1,0)+IFERROR(-F12/(1+Hypothèses!$C$34)^2,0)+IFERROR(-G12/(1+Hypothèses!$C$34)^3,0)+IFERROR(-H12/(1+Hypothèses!$C$34)^4,0)+IFERROR(-I12/(1+Hypothèses!$C$34)^5,0))/5+IFERROR(Hypothèses!$C$32*E4,0) -> -60.848754 | F14: =(IFERROR(-F12/(1+Hypothèses!$C$34)^1,0)+IFERROR(-G12/(1+Hypothèses!$C$34)^2,0)+IFERROR(-H12/(1+Hypothèses!$C$34)^3,0)+IFERROR(-I12/(1+Hypothèses!$C$34)^4,0)+IFERROR(-J12/(1+Hypothèses!$C$34)^5,0))/5+IFERROR(Hypothèses!$C$32*F4,0) -> -61.195805 | G14: =(IFERROR(-G12/(1+Hypothèses!$C$34)^1,0)+IFERROR(-H12/(1+Hypothèses!$C$34)^2,0)+IFERROR(-I12/(1+Hypothèses!$C$34)^3,0)+IFERROR(-J12/(1+Hypothèses!$C$34)^4,0)+IFERROR(-K12/(1+Hypothèses!$C$34)^5,0))/5+IFERROR(Hypothèses!$C$32*G4,0) -> -61.551897 | H14: =(IFERROR(-H12/(1+Hypothèses!$C$34)^1,0)+IFERROR(-I12/(1+Hypothèses!$C$34)^2,0)+IFERROR(-J12/(1+Hypothèses!$C$34)^3,0)+IFERROR(-K12/(1+Hypothèses!$C$34)^4,0)+IFERROR(-L12/(1+Hypothèses!$C$34)^5,0))/5+IFERROR(Hypothèses!$C$32*H4,0) -> -61.917592 | I14: =(IFERROR(-I12/(1+Hypothèses!$C$34)^1,0)+IFERROR(-J12/(1+Hypothèses!$C$34)^2,0)+IFERROR(-K12/(1+Hypothèses!$C$34)^3,0)+IFERROR(-L12/(1+Hypothèses!$C$34)^4,0)+IFERROR(-M12/(1+Hypothèses!$C$34)^5,0))/5+IFERROR(Hypothèses!$C$32*I4,0) -> -62.293479 | J14: =(IFERROR(-J12/(1+Hypothèses!$C$34)^1,0)+IFERROR(-K12/(1+Hypothèses!$C$34)^2,0)+IFERROR(-L12/(1+Hypothèses!$C$34)^3,0)+IFERROR(-M12/(1+Hypothèses!$C$34)^4,0)+IFERROR(-N12/(1+Hypothèses!$C$34)^5,0))/5+IFERROR(Hypothèses!$C$32*J4,0) -> -62.680174 | K14: =(IFERROR(-K12/(1+Hypothèses!$C$34)^1,0)+IFERROR(-L12/(1+Hypothèses!$C$34)^2,0)+IFERROR(-M12/(1+Hypothèses!$C$34)^3,0)+IFERROR(-N12/(1+Hypothèses!$C$34)^4,0)+IFERROR(-O12/(1+Hypothèses!$C$34)^5,0))/5+IFERROR(Hypothèses!$C$32*K4,0) -> -63.078324 | ... AD14: =(IFERROR(-AD12/(1+Hypothèses!$C$34)^1,0)+IFERROR(-AE12/(1+Hypothèses!$C$34)^2,0)+IFERROR(-AF12/(1+Hypothèses!$C$34)^3,0)+IFERROR(-AG12/(1+Hypothèses!$C$34)^4,0)+IFERROR(-AH12/(1+Hypothèses!$C$34)^5,0))/5+IFERROR(Hypothèses!$C$32*AD4,0) -> -58.217881 | AE14: =(IFERROR(-AE12/(1+Hypothèses!$C$34)^1,0)+IFERROR(-AF12/(1+Hypothèses!$C$34)^2,0)+IFERROR(-AG12/(1+Hypothèses!$C$34)^3,0)+IFERROR(-AH12/(1+Hypothèses!$C$34)^4,0))/4+IFERROR(Hypothèses!$C$32*AE4,0) -> -57.997598 | AF14: =(IFERROR(-AF12/(1+Hypothèses!$C$34)^1,0)+IFERROR(-AG12/(1+Hypothèses!$C$34)^2,0)+IFERROR(-AH12/(1+Hypothèses!$C$34)^3,0))/3+IFERROR(Hypothèses!$C$32*AF4,0) -> -57.752724 | AG14: =(IFERROR(-AG12/(1+Hypothèses!$C$34)^1,0)+IFERROR(-AH12/(1+Hypothèses!$C$34)^2,0))/2+IFERROR(Hypothèses!$C$32*AG4,0) -> -57.482477 | AH14: =(IFERROR(-AH12/(1+Hypothèses!$C$34)^1,0))/1+IFERROR(Hypothèses!$C$32*AH4,0) -> -57.186054
B15: D. NOUVELLES ASSIETTES A_nouvelles(t)
B16: Nouvelles assiettes A_nouvelles(t) | C16: Md€ | D16: =0 -> 0 | E16: =(Hypothèses!$C$36+Hypothèses!$C$37+Hypothèses!$C$38)*0.3333 -> 1.16655 | F16: =(Hypothèses!$C$36+Hypothèses!$C$37+Hypothèses!$C$38)*0.6667 -> 2.33345 | G16: =(Hypothèses!$C$36+Hypothèses!$C$37+Hypothèses!$C$38)*1 -> 3.5 | H16: =(Hypothèses!$C$36+Hypothèses!$C$37+Hypothèses!$C$38) -> 3.5 | I16: =(Hypothèses!$C$36+Hypothèses!$C$37+Hypothèses!$C$38) -> 3.5 | J16: =(Hypothèses!$C$36+Hypothèses!$C$37+Hypothèses!$C$38) -> 3.5 | K16: =(Hypothèses!$C$36+Hypothèses!$C$37+Hypothèses!$C$38) -> 3.5 | L16: =(Hypothèses!$C$36+Hypothèses!$C$37+Hypothèses!$C$38) -> 3.5 | M16: =(Hypothèses!$C$36+Hypothèses!$C$37+Hypothèses!$C$38) -> 3.5 | N16: =(Hypothèses!$C$36+Hypothèses!$C$37+Hypothèses!$C$38) -> 3.5 | O16: =(Hypothèses!$C$36+Hypothèses!$C$37+Hypothèses!$C$38) -> 3.5 | ... AH16: =(Hypothèses!$C$36+Hypothèses!$C$37+Hypothèses!$C$38) -> 3.5
B17: E. FONDS DE RÉSERVE (FRR) — 3 COMPARTIMENTS
B18: Socle souverain (intouchable) | C18: Md€ | D18: =Hypothèses!$C$22*Hypothèses!$C$23 -> 7.86 | E18: =Hypothèses!$C$22*Hypothèses!$C$23 -> 7.86 | F18: =Hypothèses!$C$22*Hypothèses!$C$23 -> 7.86 | G18: =Hypothèses!$C$22*Hypothèses!$C$23 -> 7.86 | H18: =Hypothèses!$C$22*Hypothèses!$C$23 -> 7.86 | I18: =Hypothèses!$C$22*Hypothèses!$C$23 -> 7.86 | J18: =Hypothèses!$C$22*Hypothèses!$C$23 -> 7.86 | K18: =Hypothèses!$C$22*Hypothèses!$C$23 -> 7.86 | ... AH18: =Hypothèses!$C$22*Hypothèses!$C$23 -> 7.86
B19: Capital croissance (compartiment dynamique) | C19: Md€ | D19: =Hypothèses!$C$22*(1-Hypothèses!$C$23) -> 18.34 | E19: =MAX(0,D19+D19*Hypothèses!$C$24*Hypothèses!$C$28+MAX(0,-E12*0.15)+E16*0.3-MIN(MAX(0,E14-E14*Hypothèses!$C$33),D19*Hypothèses!$C$27)) -> 19.331865 | F19: =MAX(0,E19+E19*Hypothèses!$C$24*Hypothèses!$C$28+MAX(0,-F12*0.15)+F16*0.3-MIN(MAX(0,F14-F14*Hypothèses!$C$33),E19*Hypothèses!$C$27)) -> 20.708515 | G19: =MAX(0,F19+F19*Hypothèses!$C$24*Hypothèses!$C$28+MAX(0,-G12*0.15)+G16*0.3-MIN(MAX(0,G14-G14*Hypothèses!$C$33),F19*Hypothèses!$C$27)) -> 22.483313 | H19: =MAX(0,G19+G19*Hypothèses!$C$24*Hypothèses!$C$28+MAX(0,-H12*0.15)+H16*0.3-MIN(MAX(0,H14-H14*Hypothèses!$C$33),G19*Hypothèses!$C$27)) -> 24.320229 | I19: =MAX(0,H19+H19*Hypothèses!$C$24*Hypothèses!$C$28+MAX(0,-I12*0.15)+I16*0.3-MIN(MAX(0,I14-I14*Hypothèses!$C$33),H19*Hypothèses!$C$27)) -> 26.221437 | J19: =MAX(0,I19+I19*Hypothèses!$C$24*Hypothèses!$C$28+MAX(0,-J12*0.15)+J16*0.3-MIN(MAX(0,J14-J14*Hypothèses!$C$33),I19*Hypothèses!$C$27)) -> 28.189188 | K19: =MAX(0,J19+J19*Hypothèses!$C$24*Hypothèses!$C$28+MAX(0,-K12*0.15)+K16*0.3-MIN(MAX(0,K14-K14*Hypothèses!$C$33),J19*Hypothèses!$C$27)) -> 30.225809 | L19: =MAX(0,K19+K19*Hypothèses!$C$24*Hypothèses!$C$28+MAX(0,-L12*0.15)+L16*0.3-MIN(MAX(0,L14-L14*Hypothèses!$C$33),K19*Hypothèses!$C$27)) -> 32.333712 | ... AH19: =MAX(0,AG19+AG19*Hypothèses!$C$24*Hypothèses!$C$28+MAX(0,-AH12*0.15)+AH16*0.3-MIN(MAX(0,AH14-AH14*Hypothèses!$C$33),AG19*Hypothèses!$C$27)) -> 102.86503
B20: FRR TOTAL | C20: Md€ | D20: =D18+D19 -> 26.2 | E20: =E18+E19 -> 27.191865 | F20: =F18+F19 -> 28.568515 | G20: =G18+G19 -> 30.343313 | H20: =H18+H19 -> 32.180229 | I20: =I18+I19 -> 34.081437 | J20: =J18+J19 -> 36.049188 | K20: =K18+K19 -> 38.085809 | ... AH20: =AH18+AH19 -> 110.72503
B21: CFРР disponible (capacité lissage) | C21: Md€ | D21: =D20*Hypothèses!$C$27 -> 2.62 | E21: =E20*Hypothèses!$C$27 -> 2.7191865 | F21: =F20*Hypothèses!$C$27 -> 2.8568515 | G21: =G20*Hypothèses!$C$27 -> 3.0343313 | H21: =H20*Hypothèses!$C$27 -> 3.2180229 | I21: =I20*Hypothèses!$C$27 -> 3.4081437 | J21: =J20*Hypothèses!$C$27 -> 3.6049188 | K21: =K20*Hypothèses!$C$27 -> 3.8085809 | ... AH21: =AH20*Hypothèses!$C$27 -> 11.072503
B22: FRR scénario bas — rendement 2% (R3) | C22: Md€ | D22: =Hypothèses!$C$22*(1-Hypothèses!$C$23) -> 18.34 | E22: =MAX(0,D22+D22*Hypothèses!$C$26*Hypothèses!$C$28+MAX(0,-E12*0.1)+E16*0.15-MIN(MAX(0,E14-E14*Hypothèses!$C$33),D22*Hypothèses!$C$27)) -> 18.771742 | F22: =MAX(0,E22+E22*Hypothèses!$C$26*Hypothèses!$C$28+MAX(0,-F12*0.1)+F16*0.15-MIN(MAX(0,F14-F14*Hypothèses!$C$33),E22*Hypothèses!$C$27)) -> 19.384564 | G22: =MAX(0,F22+F22*Hypothèses!$C$26*Hypothèses!$C$28+MAX(0,-G12*0.1)+G16*0.15-MIN(MAX(0,G14-G14*Hypothèses!$C$33),F22*Hypothèses!$C$27)) -> 20.180948 | H22: =MAX(0,G22+G22*Hypothèses!$C$26*Hypothèses!$C$28+MAX(0,-H12*0.1)+H16*0.15-MIN(MAX(0,H14-H14*Hypothèses!$C$33),G22*Hypothèses!$C$27)) -> 20.988482 | I22: =MAX(0,H22+H22*Hypothèses!$C$26*Hypothèses!$C$28+MAX(0,-I12*0.1)+I16*0.15-MIN(MAX(0,I14-I14*Hypothèses!$C$33),H22*Hypothèses!$C$27)) -> 21.80732 | J22: =MAX(0,I22+I22*Hypothèses!$C$26*Hypothèses!$C$28+MAX(0,-J12*0.1)+J16*0.15-MIN(MAX(0,J14-J14*Hypothèses!$C$33),I22*Hypothèses!$C$27)) -> 22.637623 | K22: =MAX(0,J22+J22*Hypothèses!$C$26*Hypothèses!$C$28+MAX(0,-K12*0.1)+K16*0.15-MIN(MAX(0,K14-K14*Hypothèses!$C$33),J22*Hypothèses!$C$27)) -> 23.47955 | L22: =MAX(0,K22+K22*Hypothèses!$C$26*Hypothèses!$C$28+MAX(0,-L12*0.1)+L16*0.15-MIN(MAX(0,L14-L14*Hypothèses!$C$33),K22*Hypothèses!$C$27)) -> 24.333263 | ... AH22: =MAX(0,AG22+AG22*Hypothèses!$C$26*Hypothèses!$C$28+MAX(0,-AH12*0.1)+AH16*0.15-MIN(MAX(0,AH14-AH14*Hypothèses!$C$33),AG22*Hypothèses!$C$27)) -> 46.457051
B23: F. MODULE AC-IPAA — CALCUL SÉQUENTIEL 4 NIVEAUX
B24: Absorption N0 — Péréquation inter-caisses | C24: Md€ | D24: =D14*Hypothèses!$C$33 -> -8.9256792 | E24: =E14*Hypothèses!$C$33 -> -12.169751 | F24: =F14*Hypothèses!$C$33 -> -12.239161 | G24: =G14*Hypothèses!$C$33 -> -12.310379 | H24: =H14*Hypothèses!$C$33 -> -12.383518 | I24: =I14*Hypothèses!$C$33 -> -12.458696 | J24: =J14*Hypothèses!$C$33 -> -12.536035 | K24: =K14*Hypothèses!$C$33 -> -12.615665 | ... AH24: =AH14*Hypothèses!$C$33 -> -11.437211
B25: Résidu après N0 | C25: Md€ | D25: =MAX(0,D14-D24) -> 0 | E25: =MAX(0,E14-E24) -> 0 | F25: =MAX(0,F14-F24) -> 0 | G25: =MAX(0,G14-G24) -> 0 | H25: =MAX(0,H14-H24) -> 0 | I25: =MAX(0,I14-I24) -> 0 | J25: =MAX(0,J14-J24) -> 0 | K25: =MAX(0,K14-K24) -> 0 | ... AH25: =MAX(0,AH14-AH24) -> 0
B26: Absorption N1 — FRR lissage | C26: Md€ | D26: =MIN(D25,D21) -> 0 | E26: =MIN(E25,E21) -> 0 | F26: =MIN(F25,F21) -> 0 | G26: =MIN(G25,G21) -> 0 | H26: =MIN(H25,H21) -> 0 | I26: =MIN(I25,I21) -> 0 | J26: =MIN(J25,J21) -> 0 | K26: =MIN(K25,K21) -> 0 | ... AH26: =MIN(AH25,AH21) -> 0
B27: Résidu après N1 | C27: Md€ | D27: =MAX(0,D25-D26) -> 0 | E27: =MAX(0,E25-E26) -> 0 | F27: =MAX(0,F25-F26) -> 0 | G27: =MAX(0,G25-G26) -> 0 | H27: =MAX(0,H25-H26) -> 0 | I27: =MAX(0,I25-I26) -> 0 | J27: =MAX(0,J25-J26) -> 0 | K27: =MAX(0,K25-K26) -> 0 | ... AH27: =MAX(0,AH25-AH26) -> 0
B28: Assiette élargie A_élargie(t) | C28: Md€ | D28: =D5+D16 -> 1571.8 | E28: =E5+E16 -> 1594.2016 | F28: =F5+F16 -> 1616.8904 | G28: =G5+G16 -> 1639.8696 | H28: =H5+H16 -> 1661.9769 | I28: =I5+I16 -> 1684.383 | J28: =J5+J16 -> 1707.0917 | K28: =K5+K16 -> 1730.1072 | ... AH28: =AH5+AH16 -> 2354.4231
B29: ∆τ brut calculé | C29: pts cot. | D29: =IFERROR(IF(D28>0,D27/D28,0),0) -> 0 | E29: =IFERROR(IF(E28>0,E27/E28,0),0) -> 0 | F29: =IFERROR(IF(F28>0,F27/F28,0),0) -> 0 | G29: =IFERROR(IF(G28>0,G27/G28,0),0) -> 0 | H29: =IFERROR(IF(H28>0,H27/H28,0),0) -> 0 | I29: =IFERROR(IF(I28>0,I27/I28,0),0) -> 0 | J29: =IFERROR(IF(J28>0,J27/J28,0),0) -> 0 | K29: =IFERROR(IF(K28>0,K27/K28,0),0) -> 0 | ... AH29: =IFERROR(IF(AH28>0,AH27/AH28,0),0) -> 0
B30: ∆τ(t) effectif après plafond légal | C30: pts cot. | D30: =MIN(D29,Hypothèses!$C$30) -> 0 | E30: =MIN(E29,Hypothèses!$C$30) -> 0 | F30: =MIN(F29,Hypothèses!$C$30) -> 0 | G30: =MIN(G29,Hypothèses!$C$30) -> 0 | H30: =MIN(H29,Hypothèses!$C$30) -> 0 | I30: =MIN(I29,Hypothèses!$C$30) -> 0 | J30: =MIN(J29,Hypothèses!$C$30) -> 0 | K30: =MIN(K29,Hypothèses!$C$30) -> 0 | ... AH30: =MIN(AH29,Hypothèses!$C$30) -> 0
B31: ∆τ accumulé total (plafonné) | C31: pts cot. | D31: =D30 -> 0 | E31: =MIN(D31+E30,Hypothèses!$C$31) -> 0 | F31: =MIN(E31+F30,Hypothèses!$C$31) -> 0 | G31: =MIN(F31+G30,Hypothèses!$C$31) -> 0 | H31: =MIN(G31+H30,Hypothèses!$C$31) -> 0 | I31: =MIN(H31+I30,Hypothèses!$C$31) -> 0 | J31: =MIN(I31+J30,Hypothèses!$C$31) -> 0 | K31: =MIN(J31+K30,Hypothèses!$C$31) -> 0 | L31: =MIN(K31+L30,Hypothèses!$C$31) -> 0 | ... AH31: =MIN(AG31+AH30,Hypothèses!$C$31) -> 0
B32: Recettes générées par ∆τ | C32: Md€ | D32: =D30*D28 -> 0 | E32: =E30*E28 -> 0 | F32: =F30*F28 -> 0 | G32: =G30*G28 -> 0 | H32: =H30*H28 -> 0 | I32: =I30*I28 -> 0 | J32: =J30*J28 -> 0 | K32: =K30*K28 -> 0 | ... AH32: =AH30*AH28 -> 0
B33: Clause sauvegarde N3 — excès non couvert | C33: Md€ | D33: =IF(D29>Hypothèses!$C$30,(D29-Hypothèses!$C$30)*D28,0) -> 0 | E33: =IF(E29>Hypothèses!$C$30,(E29-Hypothèses!$C$30)*E28,0) -> 0 | F33: =IF(F29>Hypothèses!$C$30,(F29-Hypothèses!$C$30)*F28,0) -> 0 | G33: =IF(G29>Hypothèses!$C$30,(G29-Hypothèses!$C$30)*G28,0) -> 0 | H33: =IF(H29>Hypothèses!$C$30,(H29-Hypothèses!$C$30)*H28,0) -> 0 | I33: =IF(I29>Hypothèses!$C$30,(I29-Hypothèses!$C$30)*I28,0) -> 0 | J33: =IF(J29>Hypothèses!$C$30,(J29-Hypothèses!$C$30)*J28,0) -> 0 | K33: =IF(K29>Hypothèses!$C$30,(K29-Hypothèses!$C$30)*K28,0) -> 0 | ... AH33: =IF(AH29>Hypothèses!$C$30,(AH29-Hypothèses!$C$30)*AH28,0) -> 0
B34: Statut clause sauvegarde | D34: =IF(D33>0,"⚠ ALERTE","✓") -> ✓ | E34: =IF(E33>0,"⚠ ALERTE","✓") -> ✓ | F34: =IF(F33>0,"⚠ ALERTE","✓") -> ✓ | G34: =IF(G33>0,"⚠ ALERTE","✓") -> ✓ | H34: =IF(H33>0,"⚠ ALERTE","✓") -> ✓ | I34: =IF(I33>0,"⚠ ALERTE","✓") -> ✓ | J34: =IF(J33>0,"⚠ ALERTE","✓") -> ✓ | K34: =IF(K33>0,"⚠ ALERTE","✓") -> ✓ | ... AH34: =IF(AH33>0,"⚠ ALERTE","✓") -> ✓
B35: G. RÉSULTATS — SOLDE AVEC IPAA
B36: Solde avec IPAA | C36: Md€ | D36: =D12+D24+D26+D32+D16 -> -23.425679 | E36: =E12+E24+E26+E32+E16 -> 55.877014 | F36: =F12+F24+F26+F32+F16 -> 57.365981 | G36: =G12+G24+G26+G32+G16 -> 58.861819 | H36: =H12+H24+H26+H32+H16 -> 59.198765 | I36: =I12+I24+I26+I32+I16 -> 59.543829 | J36: =J12+J24+J26+J32+J16 -> 59.89749 | K36: =K12+K24+K26+K32+K16 -> 60.260253 | ... AH36: =AH12+AH24+AH26+AH32+AH16 -> 54.816811
B37: Solde IPAA en % du PIB | C37: %PIB | D37: =IFERROR(D36/D4,0) -> -0.0080778204 | E37: =IFERROR(E36/E4,0) -> 0.019011096 | F37: =IFERROR(F36/F4,0) -> 0.01925752 | G37: =IFERROR(G36/G4,0) -> 0.019496272 | H37: =IFERROR(H36/H4,0) -> 0.019346504 | I37: =IFERROR(I36/I4,0) -> 0.019199882 | J37: =IFERROR(J36/J4,0) -> 0.019056468 | K37: =IFERROR(K36/K4,0) -> 0.018916322 | ... AH37: =IFERROR(AH36/AH4,0) -> 0.012637892
B38: GAIN IPAA (pts PIB) | C38: %PIB | D38: =D37-D13 -> -0.0030778204 | E38: =E37-E13 -> -0.0037436307 | F38: =F37-F13 -> -0.0033253057 | G38: =G37-G13 -> -0.0029181828 | H38: =H37-H13 -> -0.002903186 | I38: =I37-I13 -> -0.0028887277 | J38: =J37-J13 -> -0.0028748267 | K38: =K37-K13 -> -0.0028615022 | ... AH38: =AH37-AH13 -> -0.001829906
B39: H. INDICATEURS DE CONVERGENCE
B40: I1 — Convergence solde (cible ≥ 0% PIB) | D40: =IF(D37>=0,"✓ Convergence","⚠ Déficit") -> ⚠ Déficit | E40: =IF(E37>=0,"✓ Convergence","⚠ Déficit") -> ✓ Convergence | F40: =IF(F37>=0,"✓ Convergence","⚠ Déficit") -> ✓ Convergence | G40: =IF(G37>=0,"✓ Convergence","⚠ Déficit") -> ✓ Convergence | H40: =IF(H37>=0,"✓ Convergence","⚠ Déficit") -> ✓ Convergence | I40: =IF(I37>=0,"✓ Convergence","⚠ Déficit") -> ✓ Convergence | J40: =IF(J37>=0,"✓ Convergence","⚠ Déficit") -> ✓ Convergence | K40: =IF(K37>=0,"✓ Convergence","⚠ Déficit") -> ✓ Convergence | ... AH40: =IF(AH37>=0,"✓ Convergence","⚠ Déficit") -> ✓ Convergence
...

Sheet Impact_Déciles
B1: IMPACT ∆τ PAR DÉCILE — Référence : ∆τ accumulé à l'année sélectionnée
B2: Année de référence pour ∆τ : | C2: 2035 | D2: ← Modifier pour voir l'impact à une autre année
B3: ∆τ accumulé à l'année de référence : | C3: =IFERROR(INDEX(Modèle_30ans!D:AH,31,MATCH(C2,Modèle_30ans!D2:AH2,0)),0) -> 0
B5: Décile | C5: Revenu médian (€/mois) | D5: βi | E5: ∆τ global | F5: ∆τi par décile | G5: Impact mensuel (€) | H5: % du revenu net
B6: D1 | C6: =Hypothèses!$C$40 -> 800 | D6: =Hypothèses!$D$40 -> 0 | E6: =$C$3 -> 0 | F6: =E6*D6 -> 0 | G6: =C6*F6 -> 0 | H6: =IFERROR(G6/C6,0) -> 0
B7: D2 | C7: =Hypothèses!$C$41 -> 1100 | D7: =Hypothèses!$D$41 -> 0 | E7: =$C$3 -> 0 | F7: =E7*D7 -> 0 | G7: =C7*F7 -> 0 | H7: =IFERROR(G7/C7,0) -> 0
B8: D3 | C8: =Hypothèses!$C$42 -> 1350 | D8: =Hypothèses!$D$42 -> 0 | E8: =$C$3 -> 0 | F8: =E8*D8 -> 0 | G8: =C8*F8 -> 0 | H8: =IFERROR(G8/C8,0) -> 0
B9: D4 | C9: =Hypothèses!$C$43 -> 1580 | D9: =Hypothèses!$D$43 -> 0 | E9: =$C$3 -> 0 | F9: =E9*D9 -> 0 | G9: =C9*F9 -> 0 | H9: =IFERROR(G9/C9,0) -> 0
B10: D5 | C10: =Hypothèses!$C$44 -> 1900 | D10: =Hypothèses!$D$44 -> 0.15 | E10: =$C$3 -> 0 | F10: =E10*D10 -> 0 | G10: =C10*F10 -> 0 | H10: =IFERROR(G10/C10,0) -> 0
B11: D6 | C11: =Hypothèses!$C$45 -> 2350 | D11: =Hypothèses!$D$45 -> 0.25 | E11: =$C$3 -> 0 | F11: =E11*D11 -> 0 | G11: =C11*F11 -> 0 | H11: =IFERROR(G11/C11,0) -> 0
B12: D7 | C12: =Hypothèses!$C$46 -> 2980 | D12: =Hypothèses!$D$46 -> 0.4 | E12: =$C$3 -> 0 | F12: =E12*D12 -> 0 | G12: =C12*F12 -> 0 | H12: =IFERROR(G12/C12,0) -> 0
B13: D8 | C13: =Hypothèses!$C$47 -> 4100 | D13: =Hypothèses!$D$47 -> 0.65 | E13: =$C$3 -> 0 | F13: =E13*D13 -> 0 | G13: =C13*F13 -> 0 | H13: =IFERROR(G13/C13,0) -> 0
B14: D9 | C14: =Hypothèses!$C$48 -> 6000 | D14: =Hypothèses!$D$48 -> 0.85 | E14: =$C$3 -> 0 | F14: =E14*D14 -> 0 | G14: =C14*F14 -> 0 | H14: =IFERROR(G14/C14,0) -> 0
B15: D10 | C15: =Hypothèses!$C$49 -> 9500 | D15: =Hypothèses!$D$49 -> 1.2 | E15: =$C$3 -> 0 | F15: =E15*D15 -> 0 | G15: =C15*F15 -> 0 | H15: =IFERROR(G15/C15,0) -> 0
B17: Note : modifier C2 pour voir l'impact à n'importe quelle année 2025-2055
